<?xml version="1.0" encoding="utf-8"?>
<!-- This URDF was automatically created by SolidWorks to URDF Exporter! Originally created by Stephen Brawner (brawner@gmail.com) 
     Commit Version: 1.5.1-0-g916b5db  Build Version: 1.5.7152.31018
     For more information, please see http://wiki.ros.org/sw_urdf_exporter -->
<robot
  name="bulldog_description">
  <link
    name="base_link">
    <inertial>
      <origin
        xyz="-0.00018126 -0.00018572 0.11856"
        rpy="0 0 0" />
      <mass
        value="39.249" />
      <inertia
        ixx="1.6406"
        ixy="-0.0037148"
        ixz="-0.0086134"
        iyy="2.5997"
        iyz="0.0010712"
        izz="3.4136" />
    </inertial>
    <visual>
      <origin
        xyz="0 0 0"
        rpy="0 0 0" />
      <geometry>
        <mesh
          filename="package://bulldog_description/meshes/base_link.STL" />
      </geometry>
      <material
        name="">
        <color
          rgba="0 0 0 1" />
      </material>
    </visual>
    <collision>
      <origin
        xyz="0 0 0"
        rpy="0 0 0" />
      <geometry>
        <mesh
          filename="package://bulldog_description/meshes/base_link.STL" />
      </geometry>
    </collision>
  </link>
  <link
    name="wheel_link1">
    <inertial>
      <origin
        xyz="2.0959E-10 -1.1018E-07 1.4719E-10"
        rpy="0 0 0" />
      <mass
        value="10.51" />
      <inertia
        ixx="0.0988"
        ixy="9.934E-11"
        ixz="-1.5334E-10"
        iyy="0.17606"
        iyz="7.4803E-11"
        izz="0.0988" />
    </inertial>
    <visual>
      <origin
        xyz="0 0 0"
        rpy="0 0 0" />
      <geometry>
        <mesh
          filename="package://bulldog_description/meshes/wheel_link1.STL" />
      </geometry>
      <material
        name="">
        <color
          rgba="0 0.29804 0.29804 1" />
      </material>
    </visual>
    <collision>
      <origin
        xyz="0 0 0"
        rpy="0 0 0" />
      <geometry>
        <mesh
          filename="package://bulldog_description/meshes/wheel_link1.STL" />
      </geometry>
    </collision>
  </link>
  <joint
    name="wheel_joint1"
    type="continuous">
    <origin
      xyz="0.2775 0.2905 0.048"
      rpy="0 0 -3.1416" />
    <parent
      link="base_link" />
    <child
      link="wheel_link1" />
    <axis
      xyz="0 -1 0" />
  </joint>
  <link
    name="wheel_link2">
    <inertial>
      <origin
        xyz="2.6641E-11 -9.3596E-08 -2.5472E-10"
        rpy="0 0 0" />
      <mass
        value="10.51" />
      <inertia
        ixx="0.0988"
        ixy="1.7028E-11"
        ixz="2.9866E-11"
        iyy="0.17607"
        iyz="-1.2318E-10"
        izz="0.0988" />
    </inertial>
    <visual>
      <origin
        xyz="0 0 0"
        rpy="0 0 0" />
      <geometry>
        <mesh
          filename="package://bulldog_description/meshes/wheel_link2.STL" />
      </geometry>
      <material
        name="">
        <color
          rgba="0.29804 0.29804 0.29804 1" />
      </material>
    </visual>
    <collision>
      <origin
        xyz="0 0 0"
        rpy="0 0 0" />
      <geometry>
        <mesh
          filename="package://bulldog_description/meshes/wheel_link2.STL" />
      </geometry>
    </collision>
  </link>
  <joint
    name="wheel_joint2"
    type="continuous">
    <origin
      xyz="-0.2775 0.2905 0.048"
      rpy="0 0 3.1416" />
    <parent
      link="base_link" />
    <child
      link="wheel_link2" />
    <axis
      xyz="0 -1 0" />
  </joint>
  <link
    name="wheel_link3">
    <inertial>
      <origin
        xyz="2.6641E-11 -9.3596E-08 -2.5472E-10"
        rpy="0 0 0" />
      <mass
        value="10.51" />
      <inertia
        ixx="0.0988"
        ixy="1.7028E-11"
        ixz="2.9866E-11"
        iyy="0.17607"
        iyz="-1.2318E-10"
        izz="0.0988" />
    </inertial>
    <visual>
      <origin
        xyz="0 0 0"
        rpy="0 0 0" />
      <geometry>
        <mesh
          filename="package://bulldog_description/meshes/wheel_link3.STL" />
      </geometry>
      <material
        name="">
        <color
          rgba="0.29804 0.29804 0.29804 1" />
      </material>
    </visual>
    <collision>
      <origin
        xyz="0 0 0"
        rpy="0 0 0" />
      <geometry>
        <mesh
          filename="package://bulldog_description/meshes/wheel_link3.STL" />
      </geometry>
    </collision>
  </link>
  <joint
    name="wheel_joint3"
    type="continuous">
    <origin
      xyz="-0.27649 -0.2905 0.048"
      rpy="0 0 3.1416" />
    <parent
      link="base_link" />
    <child
      link="wheel_link3" />
    <axis
      xyz="0 -1 0" />
  </joint>
  <link
    name="wheel_link4">
    <inertial>
      <origin
        xyz="1.5643E-11 -1.1018E-07 -2.5563E-10"
        rpy="0 0 0" />
      <mass
        value="10.51" />
      <inertia
        ixx="0.0988"
        ixy="1.1706E-11"
        ixz="1.5821E-11"
        iyy="0.17606"
        iyz="-1.238E-10"
        izz="0.0988" />
    </inertial>
    <visual>
      <origin
        xyz="0 0 0"
        rpy="0 0 0" />
      <geometry>
        <mesh
          filename="package://bulldog_description/meshes/wheel_link4.STL" />
      </geometry>
      <material
        name="">
        <color
          rgba="0.29804 0.29804 0.29804 1" />
      </material>
    </visual>
    <collision>
      <origin
        xyz="0 0 0"
        rpy="0 0 0" />
      <geometry>
        <mesh
          filename="package://bulldog_description/meshes/wheel_link4.STL" />
      </geometry>
    </collision>
  </link>
  <joint
    name="wheel_joint4"
    type="continuous">
    <origin
      xyz="0.27851 -0.2905 0.048"
      rpy="0 0 3.1416" />
    <parent
      link="base_link" />
    <child
      link="wheel_link4" />
    <axis
      xyz="0 -1 0" />
  </joint>
  <link name="motor1_link">
    <inertial>
      <origin
        xyz="0 0 0"
        rpy="3.14159 0 1.571" />
      <mass
        value="10.51" />
      <inertia
        ixx="0.0988"
        ixy="1.1706E-11"
        ixz="1.5821E-11"
        iyy="0.17606"
        iyz="-1.238E-10"
        izz="0.0988" />
    </inertial>
	<visual>
    	<origin xyz="0 0 0" rpy="3.15 0 1.57" />
    	<geometry>
      		<mesh filename="package://bulldog_description/meshes/motor1_link.stl" />
    	</geometry>
    	<material
        	name="grey">
        	<color
          		rgba="0.29804 0.29804 0.29804 1" />
    	</material>
  	</visual>
  </link>
  <joint name="motor1_joint" type="revolute">
    <origin xyz="0.21 0 0.188" rpy="0 0 0" />
    <parent link="base_link" />
    <child link="motor1_link" />
    <axis xyz="0 0 1" rpy="0 0 0" />
    <limit lower="-3.14" upper="3.14" effort="100" velocity="0.5"/>
  </joint>
  <gazebo reference="motor1_link" />

  <link name="motor2_link">
    <inertial>
      <origin
        xyz="-0.016 0 -0.212"
        rpy="3.14 0 1.57" />
      <mass
        value="1" />
      <inertia
        ixx="0.0988"
        ixy="1.1706E-11"
        ixz="1.5821E-11"
        iyy="0.17606"
        iyz="-1.238E-10"
        izz="0.0988" />
    </inertial>
    <visual>
    	<origin xyz="-0.016 0 -0.212" rpy="3.14 0 1.57" />
    	<geometry>
      		<mesh filename="package://bulldog_description/meshes/motor2_link.stl" />
    	</geometry>
  	</visual>
  </link> 
  <joint name="motor2_joint" type="revolute">
    <origin xyz="0 0 0.212" rpy="0 0 0" />
    <parent link="motor1_link" />
    <child link="motor2_link" />
    <axis xyz="0 1 0" rpy="0 0 0" />
    <limit lower="-2.0" upper="2.0" effort="100" velocity="0.5"/>
  </joint>
  <gazebo reference="motor2_link" />

  <link name="motor3_link">
    <inertial>
      <origin
        xyz="0 0 -0.4485"
        rpy="3.14 0 1.57" />
      <mass
        value="1" />
      <inertia
        ixx="0.0988"
        ixy="1.1706E-11"
        ixz="1.5821E-11"
        iyy="0.17606"
        iyz="-1.238E-10"
        izz="0.0988" />
    </inertial>
    <visual>
    	<origin xyz="0 0 -0.4485" rpy="3.14 0 1.57" />
    	<geometry>
      		<mesh filename="package://bulldog_description/meshes/motor3_link.stl" />
    	</geometry>
  	</visual>
  </link>
  <joint name="motor3_joint" type="prismatic">
    <origin xyz="0 0 0.2365" rpy="0 0 0" />
    <parent link="motor2_link" />
    <child link="motor3_link" />
    <axis xyz="0 0 1" rpy="0 0 0" />
    <limit lower="-0.1" upper="0.3" effort="100" velocity="0.5"/>
  </joint>
  <gazebo reference="motor3_link" />
  <link
    name="sensor_link">
    <inertial>
      <origin
        xyz="-5.2042E-18 -1.5864E-19 -0.05"
        rpy="0 0 0" />
      <mass
        value="0.7854" />
      <inertia
        ixx="0.0011454"
        ixy="-3.1058E-20"
        ixz="-1.6988E-20"
        iyy="0.0011454"
        iyz="4.3923E-37"
        izz="0.00098175" />
    </inertial>
    <visual>
      <origin
        xyz="0 0 0"
        rpy="0 0 0" />
      <geometry>
        <mesh
          filename="package://bulldog_description/meshes/sensor_link.STL" />
      </geometry>
      <material
        name="">
        <color
          rgba="1 1 1 1" />
      </material>
    </visual>
    <collision>
      <origin
        xyz="0 0 0"
        rpy="0 0 0" />
      <geometry>
        <mesh
          filename="package://bulldog_description/meshes/sensor_link.STL" />
      </geometry>
    </collision>
  </link>
  <joint
    name="sensor_joint"
    type="fixed">
    <origin
      xyz="0.0050533 0 0.363"
      rpy="0 0 0" />
    <parent
      link="base_link" />
    <child
      link="sensor_link" />
    <axis
      xyz="0 0 0" />
  </joint>
  <gazebo reference="sensor_link">
      <sensor type="ray" name="head_hokuyo_sensor">
        <pose>0 0 0 0 0 0</pose>
        <visualize>false</visualize>
        <update_rate>40</update_rate>
        <ray>
          <scan>
            <horizontal>
              <samples>720</samples>
              <resolution>1</resolution>
              <min_angle>-1.570796</min_angle>
              <max_angle>1.570796</max_angle>
            </horizontal>
          </scan>
          <range>
            <min>0.10</min>
            <max>30.0</max>
            <resolution>0.01</resolution>
          </range>
          <noise>
            <type>gaussian</type>
            <mean>0.0</mean>
            <stddev>0.01</stddev>
          </noise>
        </ray>
        <plugin name="gazebo_ros_head_hokuyo_controller" filename="libgazebo_ros_laser.so">
          <topicName>scan</topicName>
          <frameName>base_link</frameName>
        </plugin>
      </sensor>
    </gazebo>
  <gazebo>
    <plugin name="skid_steer_drive_controller" filename="libgazebo_ros_skid_steer_drive.so">
      <alwaysOn>true</alwaysOn>
      <updateRate>5</updateRate>
      <leftFrontJoint>wheel_joint1</leftFrontJoint>
      <rightFrontJoint>wheel_joint4</rightFrontJoint>
     <leftRearJoint>wheel_joint2</leftRearJoint>
      <rightRearJoint>wheel_joint3</rightRearJoint> 
      <wheelSeparation>0.555</wheelSeparation> 
      <wheelDiameter>0.365</wheelDiameter>
      <torque>100</torque>
      <commandTopic>cmd_vel</commandTopic>
      <odometryTopic>odom</odometryTopic>
      <odometryFrame>odom</odometryFrame>
      <robotBaseFrame>base_link</robotBaseFrame>
      <broadcastTF>1</broadcastTF>
    </plugin>
  </gazebo>
</robot>
